# 错误处理

## 例子

### 普通用法

向上抛出错误

```zig
const std = @import("std");

pub fn main() !void {
    const file = try std.fs.cwd().openFile("does_not_exist/foo.txt", .{});
    defer file.close();
}
```

捕获错误

```zig
const std = @import("std");

pub fn main() void {
    const file = std.fs.cwd().openFile("does_not_exist/foo.txt", .{}) catch |err| {
        std.log.debug("无法打开文件: {}", .{err});
        return;
    };
    defer {
        std.log.debug("错误的时候不会到这里", .{});
        file.close();
    }
}
```

### 自定义错误

```zig
const std = @import("std");

const MyError = error{
    AAA,
    BBB,
    CCC,
};

fn demo_func(num: i32) !i32 {
    if (num < 0) {
        return MyError.AAA;
    } else {
        return num * num;
    }
}

pub fn main() void {
    const result = demo_func(-111) catch |err| {
        std.log.debug("custom error reason {}", .{err});
        return;
    };
    std.log.debug("result {d}", .{result});
}
```

### errdefer

```zig
const std = @import("std");

pub fn aa() !void {
    errdefer {
        std.log.debug("errdefer 清理垃圾", .{});
    }
    return error.aaa;
}

pub fn main() !void {
    // try aa();

    aa() catch |err| {
        std.log.debug("捕获错误 {}", .{err});
    };

    std.log.debug("正常运行", .{});
}
```
